2025-07-15 18:05:20,761 - exception_logger - ERROR - An exception occurred
Traceback (most recent call last):
  File "C:\Users\ankul\AppData\Local\Temp\ipykernel_14212\3259282278.py", line 12, in log_exception
    1 / 0
    ~~^~~
ZeroDivisionError: division by zero
